24/Aug/2022 07:36:40 PM - <module> - 818 - CRITICAL - Traceback Error: Traceback (most recent call last):
  File "C:\Users\wlongsid\AppData\Local\Programs\Python\Python310\lib\site-packages\selenium\webdriver\common\service.py", line 71, in start
    self.process = subprocess.Popen(cmd, env=self.env,
  File "C:\Users\wlongsid\AppData\Local\Programs\Python\Python310\lib\subprocess.py", line 966, in __init__
    self._execute_child(args, executable, preexec_fn, close_fds,
  File "C:\Users\wlongsid\AppData\Local\Programs\Python\Python310\lib\subprocess.py", line 1435, in _execute_child
    hp, ht, pid, tid = _winapi.CreateProcess(executable, args,
FileNotFoundError: [WinError 2] The system cannot find the file specified

During handling of the above exception, another exception occurred:

Traceback (most recent call last):
  File "c:\Users\wlongsid\OneDrive - Cisco\Documents\DEV\PY\qms_auto_update_incpection_cases\main.py", line 813, in <module>
    run.main()
  File "c:\Users\wlongsid\OneDrive - Cisco\Documents\DEV\PY\qms_auto_update_incpection_cases\main.py", line 772, in main
    self.login()
  File "c:\Users\wlongsid\OneDrive - Cisco\Documents\DEV\PY\qms_auto_update_incpection_cases\main.py", line 74, in login
    self.driver=webdriver.Chrome()
  File "C:\Users\wlongsid\AppData\Local\Programs\Python\Python310\lib\site-packages\selenium\webdriver\chrome\webdriver.py", line 70, in __init__
    super(WebDriver, self).__init__(DesiredCapabilities.CHROME['browserName'], "goog",
  File "C:\Users\wlongsid\AppData\Local\Programs\Python\Python310\lib\site-packages\selenium\webdriver\chromium\webdriver.py", line 90, in __init__
    self.service.start()
  File "C:\Users\wlongsid\AppData\Local\Programs\Python\Python310\lib\site-packages\selenium\webdriver\common\service.py", line 81, in start
    raise WebDriverException(
selenium.common.exceptions.WebDriverException: Message: 'chromedriver' executable needs to be in PATH. Please see https://chromedriver.chromium.org/home


